<?xml version="1.0" ?>
<!-- =================================================================================== -->
<!-- |    This document was autogenerated by xacro from /home/abithan_ubuntu/ros2_ws2/arm_bot/src/description/robot_core.xacro | -->
<!-- |    EDITING THIS FILE BY HAND IS NOT RECOMMENDED                                 | -->
<!-- =================================================================================== -->
<robot name="robot">
  <!-- This file is not a robot in and of itself, it just contains some useful tags that could be included in any robot -->
  <!-- Specify some colours -->
  <material name="white">
    <color rgba="1 1 1 1"/>
  </material>
  <material name="orange">
    <color rgba="1 0.3 0.1 1"/>
  </material>
  <material name="blue">
    <color rgba="0.2 0.2 1 1"/>
  </material>
  <material name="yellow">
    <color rgba="1 1 0 1"/>
  </material>
  <!-- Specify some standard inertial calculations https://en.wikipedia.org/wiki/List_of_moments_of_inertia -->
  <!-- These make use of xacro's mathematical functionality -->
  <!-- This first link called "world" is empty -->
  <link name="world"/>
  <joint name="base_joint" type="fixed">
    <origin rpy="0 0 0" xyz="0.5 0.5 0"/>
    <parent link="world"/>
    <child link="base_link"/>
  </joint>
  <link name="base_link">
    <visual>
      <origin rpy="0 0 0" xyz="0 0 0.05"/>
      <geometry>
        <box size="1 1 0.1"/>
      </geometry>
      <material name="green">
        <color rgba="0.2 1 0.2 1"/>
      </material>
    </visual>
    <collision>
      <origin rpy="0 0 0" xyz="0 0 0.05"/>
      <geometry>
        <box size="1 1 0.1"/>
      </geometry>
    </collision>
    <inertial>
      <origin rpy="0 0 0" xyz="0 0 0.05"/>
      <mass value="12"/>
      <inertia ixx="2.26" ixy="0.0" ixz="0.0" iyy="6.26" iyz="0.0" izz="8.5"/>
    </inertial>
  </link>
  <joint name="joint_1" type="revolute">
    <origin rpy="0 0 0" xyz="0 0 0.1"/>
    <parent link="base_link"/>
    <child link="link_1"/>
    <axis xyz="0 0 1"/>
    <limit effort="100" lower="0" upper="5.585" velocity="1"/>
    <dynamics damping="1.0" friction="1.0"/>
  </joint>
  <link name="link_1">
    <visual>
      <origin rpy="0 0 0" xyz="0 0 0.299085"/>
      <geometry>
        <cylinder length="0.59817" radius="0.07493"/>
      </geometry>
      <material name="blue"/>
    </visual>
    <collision>
      <origin rpy="0 0 0" xyz="0 0 0.299085"/>
      <geometry>
        <cylinder length="0.59817" radius="0.07493"/>
      </geometry>
    </collision>
    <inertial>
      <origin rpy="0 0 0" xyz="0 0 0.299085"/>
      <mass value="0.5"/>
      <inertia ixx="0.015610452649999999" ixy="0.0" ixz="0.0" iyy="0.015610452649999999" iyz="0.0" izz="0.0014036262249999998"/>
    </inertial>
  </link>
  <joint name="joint_1_shoulder" type="fixed">
    <origin rpy="0 0 0" xyz="0 0 0.6731"/>
    <parent link="link_1"/>
    <child link="shoulder"/>
  </joint>
  <link name="shoulder">
    <visual>
      <origin rpy="1.5707963267948966 0 0" xyz="0 0.046835 0"/>
      <geometry>
        <cylinder length="0.24353" radius="0.07493"/>
      </geometry>
      <material name="blue"/>
    </visual>
    <collision>
      <origin rpy="0 0 1.5707963267948966" xyz="0 0.046835 0"/>
      <geometry>
        <cylinder length="0.24353" radius="0.07493"/>
      </geometry>
    </collision>
    <inertial>
      <origin rpy="0 0 1.5707963267948966" xyz="0 0.046835 0"/>
      <mass value="0.5"/>
      <inertia ixx="0.0031729323166666667" ixy="0.0" ixz="0.0" iyy="0.0031729323166666667" iyz="0.0" izz="0.0014036262249999998"/>
    </inertial>
  </link>
  <joint name="joint_2" type="revolute">
    <origin rpy="0 0 0" xyz="0 0.24353 0"/>
    <parent link="shoulder"/>
    <child link="link_2"/>
    <axis xyz="0 -1 0"/>
    <limit effort="100" lower="-1" upper="3.363" velocity="1"/>
    <dynamics damping="1.0" friction="1.0"/>
  </joint>
  <link name="link_2">
    <visual>
      <origin rpy="4.71238898038469 0 0" xyz="0.1415 0 0"/>
      <geometry>
        <!-- <cylinder length="${link_2_length}" radius="${link_2_radius}" /> -->
        <mesh filename="package://arm_bot/meshes/puma_link3.stl" scale="26.15 26.15 26.15"/>
      </geometry>
      <material name="orange"/>
    </visual>
    <collision>
      <origin rpy="0 1.5707963267948966 0" xyz="0.1415 0 0"/>
      <geometry>
        <cylinder length="0.735" radius="0.065278"/>
        <!-- <mesh filename="package://arm_bot/meshes/puma_link3.stl" scale="0.01 0.01 0.01"/> -->
      </geometry>
    </collision>
    <inertial>
      <origin rpy="0 1.5707963267948966 0" xyz="0.1415 0 0"/>
      <mass value="1.0"/>
      <inertia ixx="0.046084054321" ixy="0.0" ixz="0.0" iyy="0.046084054321" iyz="0.0" izz="0.002130608642"/>
    </inertial>
  </link>
  <joint name="joint_3" type="revolute">
    <origin rpy="0 0 0" xyz="0.480298 -0.09398000000000001 0"/>
    <parent link="link_2"/>
    <child link="link_3"/>
    <axis xyz="0 -1 0"/>
    <limit effort="100" lower="-0.712" upper="4" velocity="1"/>
    <dynamics damping="1.0" friction="1.0"/>
  </joint>
  <link name="link_3">
    <visual>
      <origin rpy="0 0 0" xyz="0 0 -0.14986"/>
      <geometry>
        <cylinder length="0.56388" radius="0.028702"/>
      </geometry>
      <material name="yellow"/>
    </visual>
    <collision>
      <origin rpy="0 0 0" xyz="0 0 -0.14986"/>
      <geometry>
        <cylinder length="0.56388" radius="0.028702"/>
      </geometry>
    </collision>
    <inertial>
      <origin rpy="0 0 0" xyz="0 0 -0.14986"/>
      <mass value="0.5"/>
      <inertia ixx="0.0133513362005" ixy="0.0" ixz="0.0" iyy="0.0133513362005" iyz="0.0" izz="0.00020595120099999996"/>
    </inertial>
  </link>
</robot>
